Workbook

Sheet Aidez-moi
A1: Classeur d'atelier — module M03 (Excel pour l'analyse de données)
A3: Généré le 2026-09-18 par tools/classeur_M03.py. Ne pas modifier à la main : toute valeur de contrôle provient de 01_socle_donnees/data/reference/chiffres_cites.md.
A5: Feuilles et à quoi elles servent :
A6: ventes_brutes — le fichier REÇU par l'entreprise : 489 lignes × 13 colonnes, tout en texte, défauts compris (montants avec séparateur, dates manuscrites, doublons).
A7: ventes — le fichier NETTOYÉ (l'attendu du projet M01) : 480 lignes, types corrigés, montants en nombres. C'est la feuille de travail du module.
A8: produits · clients · magasins · vendeurs · objectifs — les référentiels, pour les recherches (RECHERCHEX, INDEX/EQUIV) et le rapprochement des objectifs.
A9: Calculs — une ligne par fonction de la fiche : le nom affiché, la formule telle qu'elle est stockée, la valeur attendue, la valeur rendue, et une colonne de contrôle.
A10: TCD — le tableau croisé que votre TCD doit reproduire, construit au COUNTIFS/SUMIFS. Si votre TCD ne rend pas ces nombres, l'un des deux a tort.
A11: Mensuel — le chiffre d'affaires mois par mois et l'objectif correspondant, avec le doute à lire avant toute conclusion de performance.
A13: Trois choses à vérifier avant de toucher à une formule :
A14: 1. la barre de formule montre ce que la cellule CONTIENT ; l'affichage montre ce qu'elle MONTRE ;
A15: 2. 486 montants sur 489 de la feuille ventes_brutes sont du texte : un =SOMME() y renvoie 0, et ce n'est pas une erreur du tableur ;
... A18: En cas d'écart avec le manuel : relancer `python3 01_socle_donnees/scripts/chiffres_manuel.py M01 M02 M03` puis `python3 tools/classeur_M03.py`.

Sheet ventes_brutes
A1: n_ticket | B1: date | C1: heure | D1: magasin | E1: vendeur | F1: client | G1: produit | H1: categorie | I1: quantite | J1: prix_unitaire_ht | K1: remise | L1: montant_ht | M1: montant_ttc
A2: T05-250101-075845 | B2: 2025-01-01 | C2: 11:01 | D2: Magasin 5 — Kaya Marché | E2: Moussa Ilboudo | F2: 10857 | G2: Plâtre de construction 25 kg — réf 1 | H2: Matériaux | I2: 11 | J2: 4500 | K2: 0.03 | L2: 48015 | M2: 56 658
A3: T05-250101-075846 | B3: 2025-01-01 | C3: 09:32 | D3: Magasin 5 — Kaya Marché | E3: Salamatu Sankara | F3: 0 | G3: Gravier 15/25 (m3) — réf 2 | H3: Matériaux | I3: 2000 | J3: 21950 | K3: 0.0 | L3: 43900 | M3: 51 802
A4: T05-250101-075847 | B4: 2025-01-01 | C4: 07:51 | D4: Magasin 5 — Kaya Marché | E4: Salamatu Sankara | F4: 17552 | G4: Sable de rivière (m3) — réf 1 | H4: Matériaux | I4: 2 | J4: 25775 | K4: 0.04 | L4: 49488 | M4: 58 396
A5: T05-250101-075848 | B5: 2025-01-01 | C5: 15:17 | D5: Magasin 5 — Kaya Marché | E5: Adama Bationo | F5: 2150 | G5: Échelle aluminium 4 marches — réf 1 | H5: Consommables | I5: 6 | J5: 8275 | K5: 0.0 | L5: 49650 | M5: 58 587
A6: T05-250101-075849 | B6: 2025-01-01 | C6: 10:33 | D6: Magasin 5 — Kaya Marché | E6: Adama Bationo | F6: 0 | G6: Sable de rivière (m3) — réf 1 | H6: Matériaux | I6: 3 | J6: 26325 | K6: 0.0 | L6: 78975 | M6: 93 191
A7: T05-250101-075850 | B7: 2025-01-01 | C7: 18:08 | D7: Magasin 5 — Kaya Marché | E7: Moussa Ilboudo | F7: 0 | G7: Ciment CPJ45 50 kg — réf 2 | H7: Matériaux | I7: 12 | J7: 6550 | K7: 0.0 | L7: 78600 | M7: 92 748
A8: T05-250101-075851 | B8: 2025-01-01 | C8: 13:22 | D8: Magasin 5 — Kaya Marché | E8: Adama Bationo | F8: 10176 | G8: Hourdis creux 12 — réf 1 | H8: Matériaux | I8: 6 | J8: 1025 | K8: 0.0 | L8: 6150 | M8: 7 257
A9: T05-250101-075852 | B9: 2025-01-01 | C9: 08:17 | D9: Magasin 5 — Kaya Marché | E9: Boureima Ouédraogo | F9: 11417 | G9: Meuleuse 125 mm — réf 2 | H9: Quincaillerie | I9: 9 | J9: 5850 | K9: 0.0 | L9: 52650 | M9: 62 127
A10: T05-250101-075853 | B10: 01/01/2025 | C10: 16:15 | D10: Magasin 5 — Kaya Marché | E10: Salamatu Sankara | F10: 1519 | G10: Fil de fer recuit (kg) — réf 2 | H10: Quincaillerie | I10: 3 | J10: 2000 | K10: 0.04 | L10: 5760 | M10: 6 797
A11: T05-250101-075854 | B11: 2025-01-01 | C11: 08:21 | D11: Magasin 5 — Kaya Marché | E11: Salamatu Sankara | F11: 6969 | G11: Casque de chantier — réf 1 | H11: Consommables | I11: 2 | J11: 8300 | K11: 0.0 | L11: 16600 | M11: 19 588
A12: T05-250101-075855 | B12: 2025-01-01 | C12: 15:35 | D12: Magasin 5 — Kaya Marché | E12: Boureima Ouédraogo | F12: 17857 | G12: Sac de transport 100 kg — réf 1 | H12: Consommables | I12: 2 | J12: 8525 | K12: 0.07 | L12: 15856 | M12: 18 710
... A20: T05-250101-075863 | B20: 01/01/2025 | C20: 08:54 | D20: Magasin 5 — Kaya Marché | E20: Adama Bationo | F20: 20824 | G20: Régulateur de charge 10 A — réf 2 | H20: Electricité | I20: 4 | J20: 11625 | K20: 0.0 | L20: 46500 | M20: 54 870
A21: T05-250101-075864 | B21: 2025-01-01 | C21: 16:58 | D21: Magasin 5 — Kaya Marché | E21: Salamatu Sankara | G21: Colle à carrelage 25 kg — réf 2 | H21: Matériaux | I21: 14 | J21: 4450 | K21: 0.0 | L21: 62300 | M21: 73 514
A22: T05-250101-075865 | B22: 01/01/2025 | C22: 08:16 | D22: Magasin 5 — Kaya Marché | E22: Adama Bationo | G22: Ballon d'eau chaude 50 L — réf 1 | H22: Plomberie | I22: 2 | J22: 34025 | K22: 0.0 | L22: 68050 | M22: 80 299
A23: T05-250102-075995 | B23: 2025-01-02 | C23: 16:16 | D23: Magasin 5 — Kaya Marché | E23: Boureima Ouédraogo | F23: 20631 | G23: Sable de rivière (m3) — réf 2 | H23: Matériaux | I23: 4 | J23: 27050 | K23: 0.0 | L23: 108200 | M23: 127 676
A24: T05-250102-075996 | B24: 2025-01-02 | C24: 11:23 | D24: Magasin 5 — Kaya Marché | E24: Boureima Ouédraogo | F24: 0 | G24: Brique de terre cuite — réf 2 | H24: Matériaux | I24: 7 | J24: 700 | K24: 0.0 | L24: 4900 | M24: 5 782
A25: T05-250102-075997 | B25: 2025-01-02 | C25: 09:31 | D25: Magasin 5 — Kaya Marché | E25: Boureima Ouédraogo | F25: 16066 | G25: Ciment CPJ45 50 kg — réf 1 | H25: Matériaux | I25: 12 | J25: 6100 | K25: 0.0 | L25: 73200 | M25: 86 376
A26: T05-250102-075998 | B26: 2025-01-02 | C26: 08:17 | D26: Magasin 5 — Kaya Marché | E26: Adama Bationo | F26: 17124 | G26: Hourdis creux 12 — réf 1 | H26: Matériaux | I26: 6 | J26: 1075 | K26: 0.08 | L26: 5934 | M26: 7 002
A27: T05-250102-075999 | B27: 2025-01-02 | C27: 17:27 | D27: Magasin 5 — Kaya Marché | E27: Adama Bationo | F27: 8234 | G27: Casque de chantier — réf 2 | H27: Consommables | I27: 27 | J27: 5400 | K27: 0.0 | L27: 145800 | M27: 172 044
A28: T05-250102-076000 | B28: 2025-01-02 | C28: 08:18 | D28: Magasin 5 — Kaya Marché | E28: Boureima Ouédraogo | F28: 5812 | G28: Tableau 18 modules — réf 1 | H28: Electricité | I28: 25 | J28: 8700 | K28: 0.08 | L28: 200100 | M28: 236 118
A29: T05-250102-076001 | B29: 2025-01-02 | C29: 07:43 | D29: Magasin 5 — Kaya Marché | E29: Moussa Ilboudo | F29: 9745 | G29: Pavé autobloquant — réf 2 | H29: Matériaux | I29: 3 | J29: 675 | K29: 0.0 | L29: 2025 | M29: 2 389
A30: T05-250102-076002 | B30: 02/01/2025 | C30: 10:32 | D30: Magasin 5 — Kaya Marché | E30: Salamatu Sankara | F30: 21264 | G30: Mètre ruban 5 m — réf 1 | H30: Quincaillerie | I30: 12 | J30: 7475 | K30: 0.04 | L30: 86112 | M30: 101 612
A31: T05-250102-076003 | B31: 2025-01-02 | C31: 10:37 | D31: Magasin 5 — Kaya Marché | E31: Boureima Ouédraogo | F31: 20263 | G31: Ciment CPJ45 50 kg — réf 1 | H31: Matériaux | I31: 1 | J31: 6100 | K31: 0.0 | L31: 6100 | M31: 7 198
A32: T05-250102-076004 | B32: 2025-01-02 | C32: 07:12 | D32: Magasin 5 — Kaya Marché | E32: Salamatu Sankara | G32: Tube PVC évacuation 100 mm (ml) — réf 1 | H32: Plomberie | I32: 5000 | J32: 3500 | K32: 0.0 | L32: 17500 | M32: 20 650
A33: T05-250102-076005 | B33: 2025-01-02 | C33: 08:40 | D33: Magasin 5 — Kaya Marché | E33: Boureima Ouédraogo | F33: 16610 | G33: Peinture glycéro 1 L — réf 2 | H33: Peinture | I33: 17 | J33: 3925 | K33: 0.0 | L33: 66725 | M33: 78 735
A34: T05-250102-076006 | B34: 02/01/2025 | C34: 12:58 | D34: Magasin 5 — Kaya Marché | E34: Boureima Ouédraogo | G34: Colle à carrelage 25 kg — réf 2 | H34: Matériaux | I34: 5 | J34: 4300 | K34: 0.04 | L34: 20640 | M34: 24 355
A35: T05-250102-076007 | B35: 2025-01-02 | C35: 18:53 | D35: Magasin 5 — Kaya Marché | E35: Adama Bationo | F35: 2691 | G35: Raccord laiton 20/27 — réf 2 | H35: Plomberie | I35: 4 | J35: 4825 | K35: 0.04 | L35: 18528 | M35: 21 863
A36: T05-250102-076008 | B36: 2025-01-02 | C36: 14:52 | D36: Magasin 5 — Kaya Marché | E36: Salamatu Sankara | F36: 16233 | G36: Pelle carrée — réf 2 | H36: Consommables | I36: 2 | J36: 5100 | K36: 0.0 | L36: 10200 | M36: 12 036
A37: T05-250102-076009 | B37: 2025-01-02 | C37: 16:14 | D37: Magasin 5 — Kaya Marché | E37: Boureima Ouédraogo | F37: 2178 | G37: Sac de transport 100 kg — réf 1 | H37: Consommables | I37: 2 | J37: 8775 | K37: 0.04 | L37: 16848 | M37: 19 881
A38: T05-250102-076010 | B38: 2025-01-02 | C38: 12:34 | D38: Magasin 5 — Kaya Marché | E38: Salamatu Sankara | F38: 12170 | G38: Brique de terre cuite — réf 2 | H38: Matériaux | I38: 2 | J38: 675 | K38: 0.0 | L38: 1350 | M38: 1 593
A39: T05-250102-076011 | B39: 02/01/2025 | C39: 18:01 | D39: Magasin 5 — Kaya Marché | E39: Moussa Ilboudo | F39: 2474 | G39: Tout-venant (m3) — réf 1 | H39: Matériaux | I39: 4 | J39: 16375 | K39: 0.04 | L39: 62880 | M39: 74 198
A40: T05-250102-076012 | B40: 2025-01-02 | C40: 13:31 | D40: Magasin 5 — Kaya Marché | E40: Adama Bationo | F40: 4653 | G40: Parpaing 15 aggloméré — réf 2 | H40: Matériaux | I40: 5 | J40: 1400 | K40: 0.0 | L40: 7000 | M40: 8 260
A41: T05-250102-076013 | B41: 2025-01-02 | C41: 12:57 | D41: Magasin 5 — Kaya Marché | E41: Salamatu Sankara | F41: 7529 | G41: Régulateur de charge 10 A — réf 1 | H41: Electricité | I41: 3 | J41: 21675 | K41: 0.03 | L41: 63074 | M41: 74 427
A42: T05-250201-079456 | B42: 2025-02-01 | C42: 13:52 | D42: Magasin 5 — Kaya Marché | E42: Boureima Ouédraogo | F42: 3742 | G42: Té fonte 100 — réf 1 | H42: Plomberie | I42: 1 | J42: 3150 | K42: 0.04 | L42: 3024 | M42: 3 568
A43: T05-250201-079457 | B43: 2025-02-01 | C43: 09:27 | D43: Magasin 5 — Kaya Marché | E43: Moussa Ilboudo | F43: 0 | G43: Peinture glycéro 1 L — réf 1 | H43: Peinture | I43: 21 | J43: 3300 | K43: 0.0 | L43: 69300 | M43: 81 774
A44: T05-250201-079458 | B44: 2025-02-01 | C44: 18:28 | D44: Magasin 5 — Kaya Marché | E44: Salamatu Sankara | F44: 21909 | G44: Carreau de pavement 40x40 — réf 1 | H44: Matériaux | I44: 4 | J44: 1025 | K44: 0.0 | L44: 4100 | M44: 4 838
A45: T05-250201-079459 | B45: 2025-02-01 | C45: 16:55 | D45: Magasin 5 — Kaya Marché | E45: Moussa Ilboudo | F45: 21680 | G45: Lampe solaire murale — réf 1 | H45: Electricité | I45: 5 | J45: 10525 | K45: 0.03 | L45: 51046 | M45: 60 234
A46: T05-250201-079460 | B46: 2025-02-01 | C46: 18:22 | D46: Magasin 5 — Kaya Marché | E46: Salamatu Sankara | F46: 1519 | G46: Colle à carrelage 25 kg — réf 1 | H46: Matériaux | I46: 8 | J46: 6100 | K46: 0.04 | L46: 46848 | M46: 55 281
... A74: T05-250203-079681 | B74: 2025-02-03 | C74: 07:33 | D74: Magasin 5 — Kaya Marché | E74: Salamatu Sankara | F74: 23278 | G74: Antirouille rouge brique 1 L — réf 2 | H74: Peinture | I74: 3 | J74: 6800 | K74: 0.03 | L74: 19788 | M74: 23 350
...

Sheet ventes
A1: n_ticket | B1: date | C1: heure | D1: magasin | E1: vendeur | F1: client | G1: produit | H1: categorie | I1: quantite | J1: prix_unitaire_ht | K1: remise | L1: montant_ht | M1: montant_ttc | N1: montant recalculé (colonne utilitaire)
A2: T05-250101-075845 | B2: 45658 | C2: 11:01 | D2: Magasin 5 — Kaya Marché | E2: Moussa Ilboudo | F2: 10857 | G2: Plâtre de construction 25 kg — réf 1 | H2: Matériaux | I2: 11 | J2: 4500 | K2: 0.03 | L2: 48015 | M2: 56658 | N2: =ROUND(I2*J2*(1-K2),0)
A3: T05-250101-075846 | B3: 45658 | C3: 09:32 | D3: Magasin 5 — Kaya Marché | E3: Salamatu Sankara | F3: 0 | G3: Gravier 15/25 (m3) — réf 2 | H3: Matériaux | I3: 2 | J3: 21950 | K3: 0 | L3: 43900 | M3: 51802 | N3: =ROUND(I3*J3*(1-K3),0)
A4: T05-250101-075847 | B4: 45658 | C4: 07:51 | D4: Magasin 5 — Kaya Marché | E4: Salamatu Sankara | F4: 17552 | G4: Sable de rivière (m3) — réf 1 | H4: Matériaux | I4: 2 | J4: 25775 | K4: 0.04 | L4: 49488 | M4: 58396 | N4: =ROUND(I4*J4*(1-K4),0)
A5: T05-250101-075848 | B5: 45658 | C5: 15:17 | D5: Magasin 5 — Kaya Marché | E5: Adama Bationo | F5: 2150 | G5: Échelle aluminium 4 marches — réf 1 | H5: Consommables | I5: 6 | J5: 8275 | K5: 0 | L5: 49650 | M5: 58587 | N5: =ROUND(I5*J5*(1-K5),0)
A6: T05-250101-075849 | B6: 45658 | C6: 10:33 | D6: Magasin 5 — Kaya Marché | E6: Adama Bationo | F6: 0 | G6: Sable de rivière (m3) — réf 1 | H6: Matériaux | I6: 3 | J6: 26325 | K6: 0 | L6: 78975 | M6: 93191 | N6: =ROUND(I6*J6*(1-K6),0)
A7: T05-250101-075850 | B7: 45658 | C7: 18:08 | D7: Magasin 5 — Kaya Marché | E7: Moussa Ilboudo | F7: 0 | G7: Ciment CPJ45 50 kg — réf 2 | H7: Matériaux | I7: 12 | J7: 6550 | K7: 0 | L7: 78600 | M7: 92748 | N7: =ROUND(I7*J7*(1-K7),0)
A8: T05-250101-075851 | B8: 45658 | C8: 13:22 | D8: Magasin 5 — Kaya Marché | E8: Adama Bationo | F8: 10176 | G8: Hourdis creux 12 — réf 1 | H8: Matériaux | I8: 6 | J8: 1025 | K8: 0 | L8: 6150 | M8: 7257 | N8: =ROUND(I8*J8*(1-K8),0)
A9: T05-250101-075852 | B9: 45658 | C9: 08:17 | D9: Magasin 5 — Kaya Marché | E9: Boureima Ouédraogo | F9: 11417 | G9: Meuleuse 125 mm — réf 2 | H9: Quincaillerie | I9: 9 | J9: 5850 | K9: 0 | L9: 52650 | M9: 62127 | N9: =ROUND(I9*J9*(1-K9),0)
A10: T05-250101-075853 | B10: 45658 | C10: 16:15 | D10: Magasin 5 — Kaya Marché | E10: Salamatu Sankara | F10: 1519 | G10: Fil de fer recuit (kg) — réf 2 | H10: Quincaillerie | I10: 3 | J10: 2000 | K10: 0.04 | L10: 5760 | M10: 6797 | N10: =ROUND(I10*J10*(1-K10),0)
A11: T05-250101-075854 | B11: 45658 | C11: 08:21 | D11: Magasin 5 — Kaya Marché | E11: Salamatu Sankara | F11: 6969 | G11: Casque de chantier — réf 1 | H11: Consommables | I11: 2 | J11: 8300 | K11: 0 | L11: 16600 | M11: 19588 | N11: =ROUND(I11*J11*(1-K11),0)
A12: T05-250101-075855 | B12: 45658 | C12: 15:35 | D12: Magasin 5 — Kaya Marché | E12: Boureima Ouédraogo | F12: 17857 | G12: Sac de transport 100 kg — réf 1 | H12: Consommables | I12: 2 | J12: 8525 | K12: 0.07 | L12: 15856 | M12: 18710 | N12: =ROUND(I12*J12*(1-K12),0)
A13: T05-250101-075856 | B13: 45658 | C13: 07:27 | D13: Magasin 5 — Kaya Marché | E13: Boureima Ouédraogo | F13: 17861 | G13: Hourdis creux 12 — réf 1 | H13: Matériaux | I13: 8 | J13: 1075 | K13: 0 | L13: 8600 | M13: 10148 | N13: =ROUND(I13*J13*(1-K13),0)
... A20: T05-250101-075863 | B20: 45658 | C20: 08:54 | D20: Magasin 5 — Kaya Marché | E20: Adama Bationo | F20: 20824 | G20: Régulateur de charge 10 A — réf 2 | H20: Electricité | I20: 4 | J20: 11625 | K20: 0 | L20: 46500 | M20: 54870 | N20: =ROUND(I20*J20*(1-K20),0)
A21: T05-250101-075864 | B21: 45658 | C21: 16:58 | D21: Magasin 5 — Kaya Marché | E21: Salamatu Sankara | G21: Colle à carrelage 25 kg — réf 2 | H21: Matériaux | I21: 14 | J21: 4450 | K21: 0 | L21: 62300 | M21: 73514 | N21: =ROUND(I21*J21*(1-K21),0)
A22: T05-250101-075865 | B22: 45658 | C22: 08:16 | D22: Magasin 5 — Kaya Marché | E22: Adama Bationo | G22: Ballon d'eau chaude 50 L — réf 1 | H22: Plomberie | I22: 2 | J22: 34025 | K22: 0 | L22: 68050 | M22: 80299 | N22: =ROUND(I22*J22*(1-K22),0)
A23: T05-250102-075995 | B23: 45659 | C23: 16:16 | D23: Magasin 5 — Kaya Marché | E23: Boureima Ouédraogo | F23: 20631 | G23: Sable de rivière (m3) — réf 2 | H23: Matériaux | I23: 4 | J23: 27050 | K23: 0 | L23: 108200 | M23: 127676 | N23: =ROUND(I23*J23*(1-K23),0)
A24: T05-250102-075996 | B24: 45659 | C24: 11:23 | D24: Magasin 5 — Kaya Marché | E24: Boureima Ouédraogo | F24: 0 | G24: Brique de terre cuite — réf 2 | H24: Matériaux | I24: 7 | J24: 700 | K24: 0 | L24: 4900 | M24: 5782 | N24: =ROUND(I24*J24*(1-K24),0)
A25: T05-250102-075997 | B25: 45659 | C25: 09:31 | D25: Magasin 5 — Kaya Marché | E25: Boureima Ouédraogo | F25: 16066 | G25: Ciment CPJ45 50 kg — réf 1 | H25: Matériaux | I25: 12 | J25: 6100 | K25: 0 | L25: 73200 | M25: 86376 | N25: =ROUND(I25*J25*(1-K25),0)
A26: T05-250102-075998 | B26: 45659 | C26: 08:17 | D26: Magasin 5 — Kaya Marché | E26: Adama Bationo | F26: 17124 | G26: Hourdis creux 12 — réf 1 | H26: Matériaux | I26: 6 | J26: 1075 | K26: 0.08 | L26: 5934 | M26: 7002 | N26: =ROUND(I26*J26*(1-K26),0)
A27: T05-250102-075999 | B27: 45659 | C27: 17:27 | D27: Magasin 5 — Kaya Marché | E27: Adama Bationo | F27: 8234 | G27: Casque de chantier — réf 2 | H27: Consommables | I27: 27 | J27: 5400 | K27: 0 | L27: 145800 | M27: 172044 | N27: =ROUND(I27*J27*(1-K27),0)
A28: T05-250102-076000 | B28: 45659 | C28: 08:18 | D28: Magasin 5 — Kaya Marché | E28: Boureima Ouédraogo | F28: 5812 | G28: Tableau 18 modules — réf 1 | H28: Electricité | I28: 25 | J28: 8700 | K28: 0.08 | L28: 200100 | M28: 236118 | N28: =ROUND(I28*J28*(1-K28),0)
A29: T05-250102-076001 | B29: 45659 | C29: 07:43 | D29: Magasin 5 — Kaya Marché | E29: Moussa Ilboudo | F29: 9745 | G29: Pavé autobloquant — réf 2 | H29: Matériaux | I29: 3 | J29: 675 | K29: 0 | L29: 2025 | M29: 2389 | N29: =ROUND(I29*J29*(1-K29),0)
A30: T05-250102-076002 | B30: 45659 | C30: 10:32 | D30: Magasin 5 — Kaya Marché | E30: Salamatu Sankara | F30: 21264 | G30: Mètre ruban 5 m — réf 1 | H30: Quincaillerie | I30: 12 | J30: 7475 | K30: 0.04 | L30: 86112 | M30: 101612 | N30: =ROUND(I30*J30*(1-K30),0)
A31: T05-250102-076003 | B31: 45659 | C31: 10:37 | D31: Magasin 5 — Kaya Marché | E31: Boureima Ouédraogo | F31: 20263 | G31: Ciment CPJ45 50 kg — réf 1 | H31: Matériaux | I31: 1 | J31: 6100 | K31: 0 | L31: 6100 | M31: 7198 | N31: =ROUND(I31*J31*(1-K31),0)
A32: T05-250102-076004 | B32: 45659 | C32: 07:12 | D32: Magasin 5 — Kaya Marché | E32: Salamatu Sankara | G32: Tube PVC évacuation 100 mm (ml) — réf 1 | H32: Plomberie | I32: 5 | J32: 3500 | K32: 0 | L32: 17500 | M32: 20650 | N32: =ROUND(I32*J32*(1-K32),0)
A33: T05-250102-076005 | B33: 45659 | C33: 08:40 | D33: Magasin 5 — Kaya Marché | E33: Boureima Ouédraogo | F33: 16610 | G33: Peinture glycéro 1 L — réf 2 | H33: Peinture | I33: 17 | J33: 3925 | K33: 0 | L33: 66725 | M33: 78735 | N33: =ROUND(I33*J33*(1-K33),0)
A34: T05-250102-076006 | B34: 45659 | C34: 12:58 | D34: Magasin 5 — Kaya Marché | E34: Boureima Ouédraogo | G34: Colle à carrelage 25 kg — réf 2 | H34: Matériaux | I34: 5 | J34: 4300 | K34: 0.04 | L34: 20640 | M34: 24355 | N34: =ROUND(I34*J34*(1-K34),0)
A35: T05-250102-076007 | B35: 45659 | C35: 18:53 | D35: Magasin 5 — Kaya Marché | E35: Adama Bationo | F35: 2691 | G35: Raccord laiton 20/27 — réf 2 | H35: Plomberie | I35: 4 | J35: 4825 | K35: 0.04 | L35: 18528 | M35: 21863 | N35: =ROUND(I35*J35*(1-K35),0)
A36: T05-250102-076008 | B36: 45659 | C36: 14:52 | D36: Magasin 5 — Kaya Marché | E36: Salamatu Sankara | F36: 16233 | G36: Pelle carrée — réf 2 | H36: Consommables | I36: 2 | J36: 5100 | K36: 0 | L36: 10200 | M36: 12036 | N36: =ROUND(I36*J36*(1-K36),0)
A37: T05-250102-076009 | B37: 45659 | C37: 16:14 | D37: Magasin 5 — Kaya Marché | E37: Boureima Ouédraogo | F37: 2178 | G37: Sac de transport 100 kg — réf 1 | H37: Consommables | I37: 2 | J37: 8775 | K37: 0.04 | L37: 16848 | M37: 19881 | N37: =ROUND(I37*J37*(1-K37),0)
A38: T05-250102-076010 | B38: 45659 | C38: 12:34 | D38: Magasin 5 — Kaya Marché | E38: Salamatu Sankara | F38: 12170 | G38: Brique de terre cuite — réf 2 | H38: Matériaux | I38: 2 | J38: 675 | K38: 0 | L38: 1350 | M38: 1593 | N38: =ROUND(I38*J38*(1-K38),0)
A39: T05-250102-076011 | B39: 45659 | C39: 18:01 | D39: Magasin 5 — Kaya Marché | E39: Moussa Ilboudo | F39: 2474 | G39: Tout-venant (m3) — réf 1 | H39: Matériaux | I39: 4 | J39: 16375 | K39: 0.04 | L39: 62880 | M39: 74198 | N39: =ROUND(I39*J39*(1-K39),0)
A40: T05-250102-076012 | B40: 45659 | C40: 13:31 | D40: Magasin 5 — Kaya Marché | E40: Adama Bationo | F40: 4653 | G40: Parpaing 15 aggloméré — réf 2 | H40: Matériaux | I40: 5 | J40: 1400 | K40: 0 | L40: 7000 | M40: 8260 | N40: =ROUND(I40*J40*(1-K40),0)
A41: T05-250102-076013 | B41: 45659 | C41: 12:57 | D41: Magasin 5 — Kaya Marché | E41: Salamatu Sankara | F41: 7529 | G41: Régulateur de charge 10 A — réf 1 | H41: Electricité | I41: 3 | J41: 21675 | K41: 0.03 | L41: 63074 | M41: 74427 | N41: =ROUND(I41*J41*(1-K41),0)
A42: T05-250201-079456 | B42: 45689 | C42: 13:52 | D42: Magasin 5 — Kaya Marché | E42: Boureima Ouédraogo | F42: 3742 | G42: Té fonte 100 — réf 1 | H42: Plomberie | I42: 1 | J42: 3150 | K42: 0.04 | L42: 3024 | M42: 3568 | N42: =ROUND(I42*J42*(1-K42),0)
A43: T05-250201-079457 | B43: 45689 | C43: 09:27 | D43: Magasin 5 — Kaya Marché | E43: Moussa Ilboudo | F43: 0 | G43: Peinture glycéro 1 L — réf 1 | H43: Peinture | I43: 21 | J43: 3300 | K43: 0 | L43: 69300 | M43: 81774 | N43: =ROUND(I43*J43*(1-K43),0)
A44: T05-250201-079458 | B44: 45689 | C44: 18:28 | D44: Magasin 5 — Kaya Marché | E44: Salamatu Sankara | F44: 21909 | G44: Carreau de pavement 40x40 — réf 1 | H44: Matériaux | I44: 4 | J44: 1025 | K44: 0 | L44: 4100 | M44: 4838 | N44: =ROUND(I44*J44*(1-K44),0)
A45: T05-250201-079459 | B45: 45689 | C45: 16:55 | D45: Magasin 5 — Kaya Marché | E45: Moussa Ilboudo | F45: 21680 | G45: Lampe solaire murale — réf 1 | H45: Electricité | I45: 5 | J45: 10525 | K45: 0.03 | L45: 51046 | M45: 60234 | N45: =ROUND(I45*J45*(1-K45),0)
A46: T05-250201-079460 | B46: 45689 | C46: 18:22 | D46: Magasin 5 — Kaya Marché | E46: Salamatu Sankara | F46: 1519 | G46: Colle à carrelage 25 kg — réf 1 | H46: Matériaux | I46: 8 | J46: 6100 | K46: 0.04 | L46: 46848 | M46: 55281 | N46: =ROUND(I46*J46*(1-K46),0)
...

Sheet produits
A1: id_produit | B1: designation | C1: categorie | D1: sous_categorie | E1: unite | F1: prix_vente_ht | G1: poids_unite_kg | H1: fournisseur | I1: reference_fournisseur | J1: tva | K1: actif
A2: 1 | B2: Ciment CPJ45 50 kg — réf 1 | C2: Matériaux | D2: Ciment & liants | E2: sac | F2: 5200 | G2: 33.17 | H2: CIMAF Sahel | I2: MAT-0001 | J2: 0.18 | K2: 1
A3: 2 | B3: Ciment CPJ45 50 kg — réf 2 | C3: Matériaux | D3: Ciment & liants | E3: sac | F3: 5575 | G3: 28.24 | H3: CIMAF Sahel | I3: MAT-0002 | J3: 0.18 | K3: 1
A4: 3 | B4: Ciment CPJ35 50 kg — réf 1 | C4: Matériaux | D4: Ciment & liants | E4: sac | F4: 5275 | G4: 55.6 | H4: CIMAF Sahel | I4: MAT-0003 | J4: 0.18 | K4: 1
A5: 4 | B5: Ciment CPJ35 50 kg — réf 2 | C5: Matériaux | D5: Ciment & liants | E5: sac | F5: 3550 | G5: 32.68 | H5: CIMAF Sahel | I5: MAT-0004 | J5: 0.18 | K5: 1
A6: 5 | B6: Chaux aérienne 25 kg — réf 1 | C6: Matériaux | D6: Ciment & liants | E6: sac | F6: 4400 | G6: 26.29 | H6: CIMAF Sahel | I6: MAT-0005 | J6: 0.18 | K6: 1
A7: 6 | B7: Chaux aérienne 25 kg — réf 2 | C7: Matériaux | D7: Ciment & liants | E7: sac | F7: 6925 | G7: 59.63 | H7: CIMAF Sahel | I7: MAT-0006 | J7: 0.18 | K7: 1
A8: 7 | B8: Plâtre de construction 25 kg — réf 1 | C8: Matériaux | D8: Ciment & liants | E8: sac | F8: 3750 | G8: 33.06 | H8: CIMAF Sahel | I8: MAT-0007 | J8: 0.18 | K8: 1
A9: 8 | B9: Plâtre de construction 25 kg — réf 2 | C9: Matériaux | D9: Ciment & liants | E9: sac | F9: 5150 | G9: 67.68 | H9: CIMAF Sahel | I9: MAT-0008 | J9: 0.18 | K9: 1
A10: 9 | B10: Colle à carrelage 25 kg — réf 1 | C10: Matériaux | D10: Ciment & liants | E10: sac | F10: 5075 | G10: 38.98 | H10: CIMAF Sahel | I10: MAT-0009 | J10: 0.18 | K10: 1
A11: 10 | B11: Colle à carrelage 25 kg — réf 2 | C11: Matériaux | D11: Ciment & liants | E11: sac | F11: 3775 | G11: 34.15 | H11: CIMAF Sahel | I11: MAT-0010 | J11: 0.18 | K11: 1
A12: 11 | B12: Enduit de lissage 20 kg — réf 1 | C12: Matériaux | D12: Ciment & liants | E12: sac | F12: 6300 | G12: 47.56 | H12: CIMAF Sahel | I12: MAT-0011 | J12: 0.18 | K12: 1
A13: 12 | B13: Enduit de lissage 20 kg — réf 2 | C13: Matériaux | D13: Ciment & liants | E13: sac | F13: 5500 | G13: 56.29 | H13: CIMAF Sahel | I13: MAT-0012 | J13: 0.18 | K13: 1
... A155: 154 | B155: Casque de chantier — réf 2 | C155: Consommables | D155: Divers chantier | E155: unité | F155: 4675 | G155: 0.36 | H155: EPI Faso | I155: CON-0154 | J155: 0.18 | K155: 1

Sheet clients
A1: id_client | B1: nom | C1: type_client | D1: ville | E1: region | F1: telephone | G1: email | H1: date_creation | I1: segment | J1: conditions_paiement | K1: plafond_credit
A2: 125 | B2: SARL g | C2: Professionnel | D2: Kaya | E2: Centre-Nord | F2: +226 78 38 90 25 54 | G2: contact125@entreprise.bf | H2: 2020-09-13 | I2: Standard | J2: 30 j | K2: 0
A3: 182 | B3: Menage 00182 | C3: Particulier | D3: Ziniaré | E3: Plateau-Central | F3: +226 74 35 48 20 75 | H3: 2016-04-20 | I3: Standard | J3: Comptant | K3: 0
A4: 246 | B4: Ets o | C4: Professionnel | D4: Ouagadougou | E4: Centre | F4: +226 79 44 35 43 60 | G4: contact246@gmail.com | H4: 2016-10-16 | I4: Standard | J4: Comptant | K4: 250000
A5: 261 | B5: Chantiers o | C5: Professionnel | D5: Ziniaré | E5: Plateau-Central | F5: +226 71 11 37 22 57 | G5: contact261@gmail.com | H5: 2024-01-24 | I5: Standard | J5: Comptant | K5: 0
A6: 353 | B6: Menage 00353 | C6: Particulier | D6: Ouagadougou | E6: Centre | F6: +226 74 52 20 61 48 | H6: 2020-09-14 | I6: Standard | J6: Comptant | K6: 1500000
A7: 367 | B7: Chantiers o | C7: Entreprise | D7: Ouagadougou | E7: Centre | F7: +226 78 69 90 11 87 | G7: contact367@gmail.com | H7: 2020-05-04 | I7: Argent | J7: Comptant | K7: 0
A8: 475 | B8: Menage 00475 | C8: Particulier | D8: Bobo-Dioulasso | E8: Hauts-Bassins | F8: +226 74 86 77 42 69 | H8: 2021-07-30 | I8: Argent | J8: Comptant | K8: 1500000
A9: 557 | B9: Chantiers é | C9: Professionnel | D9: Ouagadougou | E9: Centre | F9: +226 70 47 24 43 96 | G9: contact557@yahoo.fr | H9: 2025-07-12 | I9: Standard | J9: 30 j | K9: 0
A10: 640 | B10: Menage 00640 | C10: Particulier | D10: Koudougou | E10: Centre-Ouest | F10: +226 72 50 85 25 80 | H10: 2016-05-03 | I10: Standard | J10: Comptant | K10: 250000
A11: 728 | B11: Menage 00728 | C11: Particulier | D11: Ouagadougou | E11: Centre | F11: +226 75 67 28 59 91 | H11: 2024-10-22 | I11: Or | J11: Comptant | K11: 1500000
A12: 756 | B12: Chantiers d | C12: Professionnel | D12: Ouagadougou | E12: Centre | F12: +226 74 30 29 17 11 | G12: contact756@entreprise.bf | H12: 2016-08-30 | I12: Standard | J12: Comptant | K12: 0
A13: 883 | B13: Menage 00883 | C13: Particulier | D13: Ziniaré | E13: Plateau-Central | F13: +226 72 83 12 97 41 | H13: 2016-01-07 | I13: Standard | J13: Comptant | K13: 0
A14: 984 | B14: Ets B | C14: Entreprise | D14: Ouagadougou | E14: Centre | F14: +226 71 73 97 10 77 | G14: contact984@yahoo.fr | H14: 2018-02-25 | I14: Argent | J14: 30 j | K14: 0
A15: 1056 | B15: Ets T | C15: Administration | D15: Ouagadougou | E15: Centre | F15: +226 73 79 65 73 74 | H15: 2023-05-01 | I15: Standard | J15: Comptant | K15: 0
A16: 1117 | B16: Menage 01117 | C16: Particulier | D16: Kaya | E16: Centre-Nord | F16: +226 75 34 21 77 74 | H16: 2018-02-09 | I16: Argent | J16: 30 j | K16: 1500000
A17: 1144 | B17: Menage 01144 | C17: Particulier | D17: Ouagadougou | E17: Centre | F17: +226 70 74 56 21 36 | H17: 2024-08-19 | I17: Argent | J17: 30 j | K17: 0
A18: 1242 | B18: Menage 01242 | C18: Particulier | D18: Kaya | E18: Centre-Nord | F18: +226 76 76 90 49 66 | H18: 2021-05-16 | I18: Argent | J18: Comptant | K18: 1500000
A19: 1357 | B19: Menage 01357 | C19: Particulier | D19: Bobo-Dioulasso | E19: Hauts-Bassins | F19: +226 78 46 29 79 29 | H19: 2019-08-23 | I19: Standard | J19: Comptant | K19: 250000
A20: 1359 | B20: Menage 01359 | C20: Particulier | D20: Ouagadougou | E20: Centre | F20: +226 70 73 77 42 18 | H20: 2016-12-08 | I20: Standard | J20: 60 j | K20: 1500000
A21: 1374 | B21: Menage 01374 | C21: Particulier | D21: Koudougou | E21: Centre-Ouest | F21: +226 72 78 11 29 47 | H21: 2018-03-04 | I21: Standard | J21: 30 j | K21: 500000
A22: 1455 | B22: Menage 01455 | C22: Particulier | D22: Bobo-Dioulasso | E22: Hauts-Bassins | F22: +226 70 31 23 16 71 | H22: 2023-11-24 | I22: Standard | J22: Comptant | K22: 500000
A23: 1462 | B23: Menage 01462 | C23: Particulier | D23: Bobo-Dioulasso | E23: Hauts-Bassins | F23: +226 72 19 36 45 64 | H23: 2016-02-08 | I23: Standard | J23: Comptant | K23: 0
A24: 1469 | B24: Menage 01469 | C24: Particulier | D24: Bobo-Dioulasso | E24: Hauts-Bassins | F24: +226 76 87 26 32 64 | H24: 2025-10-14 | I24: Standard | J24: 30 j | K24: 1500000
A25: 1472 | B25: Chantiers o | C25: Professionnel | D25: Bobo-Dioulasso | E25: Hauts-Bassins | F25: +226 71 32 10 75 74 | G25: contact1472@gmail.com | H25: 2022-07-27 | I25: Standard | J25: Comptant | K25: 1500000
A26: 1508 | B26: Menage 01508 | C26: Particulier | D26: Bobo-Dioulasso | E26: Hauts-Bassins | F26: +226 79 30 85 61 89 | H26: 2021-01-23 | I26: Standard | J26: Comptant | K26: 0
A27: 1519 | B27: Menage 01519 | C27: Particulier | D27: Ouagadougou | E27: Centre | F27: +226 76 29 34 40 89 | H27: 2017-03-16 | I27: Argent | J27: Comptant | K27: 0
A28: 1616 | B28: Ets K | C28: Entreprise | D28: Bobo-Dioulasso | E28: Hauts-Bassins | F28: +226 77 86 70 24 80 | H28: 2019-02-15 | I28: Argent | J28: Comptant | K28: 250000
A29: 1635 | B29: Menage 01635 | C29: Particulier | D29: Ouagadougou | E29: Centre | F29: +226 76 10 93 37 37 | H29: 2017-06-17 | I29: Argent | J29: 60 j | K29: 5000000
A30: 1690 | B30: Menage 01690 | C30: Particulier | D30: Ouagadougou | E30: Centre | F30: +226 75 50 26 72 87 | H30: 2019-09-03 | I30: Or | J30: Comptant | K30: 1500000
A31: 1716 | B31: Societe i | C31: Professionnel | D31: Ziniaré | E31: Plateau-Central | F31: +226 75 99 19 68 56 | G31: contact1716@entreprise.bf | H31: 2021-05-14 | I31: Standard | J31: Comptant | K31: 0
A32: 1796 | B32: Societe o | C32: Entreprise | D32: Ouagadougou | E32: Centre | F32: +226 75 13 46 56 40 | G32: contact1796@gmail.com | H32: 2024-09-17 | I32: Argent | J32: Comptant | K32: 0
A33: 1854 | B33: Menage 01854 | C33: Particulier | D33: Koudougou | E33: Centre-Ouest | F33: +226 70 91 13 31 26 | H33: 2024-04-04 | I33: Standard | J33: Comptant | K33: 1500000
A34: 1934 | B34: Chantiers b | C34: Professionnel | D34: Kaya | E34: Centre-Nord | F34: +226 70 32 99 64 82 | H34: 2023-05-06 | I34: Argent | J34: Comptant | K34: 0
A35: 2149 | B35: Menage 02149 | C35: Particulier | D35: Bobo-Dioulasso | E35: Hauts-Bassins | F35: +226 70 91 14 10 84 | H35: 2020-09-27 | I35: Standard | J35: Comptant | K35: 0
A36: 2150 | B36: Chantiers r | C36: Professionnel | D36: Kaya | E36: Centre-Nord | F36: +226 71 68 16 18 32 | G36: contact2150@outlook.fr | H36: 2023-11-14 | I36: Standard | J36: 30 j | K36: 0
A37: 2178 | B37: SARL O | C37: Entreprise | D37: Ouagadougou | E37: Centre | F37: +226 72 11 97 90 22 | H37: 2021-06-02 | I37: Argent | J37: Comptant | K37: 250000
A38: 2275 | B38: Menage 02275 | C38: Particulier | D38: Bobo-Dioulasso | E38: Hauts-Bassins | F38: +226 71 67 82 74 64 | H38: 2016-01-02 | I38: Standard | J38: 30 j | K38: 500000
A39: 2296 | B39: SARL p | C39: Professionnel | D39: Ziniaré | E39: Plateau-Central | F39: +226 75 39 79 92 52 | H39: 2020-09-14 | I39: Standard | J39: 60 j | K39: 1500000
A40: 2446 | B40: Menage 02446 | C40: Particulier | D40: Kaya | E40: Centre-Nord | F40: +226 72 86 99 51 84 | H40: 2016-07-01 | I40: Standard | J40: 30 j | K40: 250000
...

Sheet magasins
A1: id_magasin | B1: nom | C1: ville | D1: quartier | E1: region | F1: type_magasin | G1: surface_m2 | H1: responsable | I1: ouverture
A2: 1 | B2: Sahel Distribution — Ouaga 2000 | C2: Ouagadougou | D2: Ouaga 2000 | E2: Centre | F2: Magasin | G2: 1450 | H2: A. Zongo | I2: 2016-03-01
A3: 2 | B3: Sahel Distribution — Gounghin | C3: Ouagadougou | D3: Gounghin | E3: Centre | F3: Magasin | G3: 900 | H3: F. Kaboré | I3: 2018-09-15
A4: 3 | B4: Sahel Distribution — Bobo Kibidwé | C4: Bobo-Dioulasso | D4: Kibidwé | E4: Hauts-Bassins | F4: Magasin | G4: 1100 | H4: S. Sanou | I4: 2017-06-01
A5: 4 | B5: Sahel Distribution — Koudougou Centre | C5: Koudougou | D5: Pole | E5: Centre-Ouest | F5: Magasin | G5: 650 | H5: R. Ouédraogo | I5: 2020-02-10
A6: 5 | B6: Sahel Distribution — Kaya Marché | C6: Kaya | D6: Marché | E6: Centre-Nord | F6: Magasin | G6: 520 | H6: I. Traoré | I6: 2021-11-05
A7: 6 | B7: Dépôt central — Zogona | C7: Ouagadougou | D7: Zogona | E7: Centre | F7: Dépôt | G7: 3200 | H7: M. Compaoré | I7: 2015-01-12

Sheet vendeurs
A1: id_vendeur | B1: nom_complet | C1: id_magasin | D1: date_embauche | E1: statut | F1: secteur_vente
A2: 1 | B2: Awa Zongo | C2: 2 | D2: 2019-08-11 | E2: Titulaire | F2: Comptoir
A3: 2 | B3: Issa Kaboré | C3: 3 | D3: 2018-07-03 | E3: Titulaire | F3: Comptoir
A4: 3 | B4: Fatoumata Sanou | C4: 4 | D4: 2022-06-21 | E4: Titulaire | F4: Comptoir
A5: 4 | B5: Boureima Ouédraogo | C5: 5 | D5: 2021-02-09 | E5: CDD | F5: Itinérant
A6: 5 | B6: Salif Traoré | C6: 1 | D6: 2017-07-04 | E6: Titulaire | F6: Itinérant
A7: 6 | B7: Mariam Compaoré | C7: 2 | D7: 2019-12-21 | E7: Titulaire | F7: Itinérant
A8: 7 | B8: Karim Sawadogo | C8: 3 | D8: 2020-05-31 | E8: Titulaire | F8: Itinérant
A9: 8 | B9: Rasmata Diallo | C9: 4 | D9: 2018-06-14 | E9: Titulaire | F9: Itinérant
A10: 9 | B10: Adama Bationo | C10: 5 | D10: 2016-07-28 | E10: Titulaire | F10: Itinérant
A11: 10 | B11: Safiatou Nikiéma | C11: 1 | D11: 2020-05-02 | E11: Titulaire | F11: Comptoir
A12: 11 | B12: Boukary Ouattara | C12: 2 | D12: 2019-05-20 | E12: Titulaire | F12: Comptoir
A13: 12 | B13: Alizéta Tapsoba | C13: 3 | D13: 2016-07-01 | E13: CDD | F13: Comptoir
... A23: 22 | B23: Nafissatou Zoungrana | C23: 3 | D23: 2018-12-13 | E23: CDD | F23: Itinérant

Sheet objectifs
A1: id_magasin | B1: annee | C1: mois | D1: annee_mois | E1: ca_objectif_ttc | F1: marge_objectif_pct
A2: 1 | B2: 2023 | C2: 1 | D2: 2023-01 | E2: 45600000 | F2: 0.195
A3: 1 | B3: 2023 | C3: 2 | D3: 2023-02 | E3: 48000000 | F3: 0.197
A4: 1 | B4: 2023 | C4: 3 | D4: 2023-03 | E4: 56640000 | F4: 0.201
A5: 1 | B5: 2023 | C5: 4 | D5: 2023-04 | E5: 54720000 | F5: 0.189
A6: 1 | B6: 2023 | C6: 5 | D6: 2023-05 | E6: 44160000 | F6: 0.187
A7: 1 | B7: 2023 | C7: 6 | D7: 2023-06 | E7: 37440000 | F7: 0.189
A8: 1 | B8: 2023 | C8: 7 | D8: 2023-07 | E8: 34560000 | F8: 0.196
A9: 1 | B9: 2023 | C9: 8 | D9: 2023-08 | E9: 38400000 | F9: 0.198
A10: 1 | B10: 2023 | C10: 9 | D10: 2023-09 | E10: 48960000 | F10: 0.192
A11: 1 | B11: 2023 | C11: 10 | D11: 2023-10 | E11: 58560000 | F11: 0.187
A12: 1 | B12: 2023 | C12: 11 | D12: 2023-11 | E12: 57600000 | F12: 0.198
A13: 1 | B13: 2023 | C13: 12 | D13: 2023-12 | E13: 55680000 | F13: 0.202
... A219: 5 | B219: 2026 | C219: 8 | D219: 2026-08 | E219: 14060000 | F219: 0.194

Sheet Calculs
A1: n° | B1: Fonction (telle que l'affiche Excel FR) | C1: Formule, telle qu'elle est stockée | D1: Valeur que la formule doit rendre | E1: Ce que la formule rend | F1: contrôle
A2: 1 | B2: NB sur la colonne des montants | C2: COUNT(ventes!M2:M481) | D2: 480 | E2: =COUNT(ventes!M2:M481) | F2: =IF(EXACT(D2,E2),"ok","à revoir") | G2: les 480 montants réellement numériques de la feuille nettoyée
A3: 2 | B3: NBVAL — compter tout ce qui est écrit | C3: COUNTA(ventes_brutes!A2:A490) | D3: 489 | E3: =COUNTA(ventes_brutes!A2:A490) | F3: =IF(EXACT(D3,E3),"ok","à revoir") | G3: les 489 lignes reçues, nombres et textes confondus
A4: 3 | B4: NB appliqué aux montants reçus | C4: COUNT(ventes_brutes!M2:M490) | D4: 0 | E4: =COUNT(ventes_brutes!M2:M490) | F4: =IF(EXACT(D4,E4),"ok","à revoir") | G4: le symptôme de l'import raté, dans le classeur : 0 montant numérique sur 489. Le CSV reçu en contient 3 (lignes 88, 179, 236), mais en collant la feuille dans un classeur ils redeviennent du texte — voyez C02 §5.1.
A5: 4 | B5: SOMME sur la feuille reçue | C5: SUM(ventes_brutes!M2:M490) | D5: 0 | E5: =SUM(ventes_brutes!M2:M490) | F5: =IF(EXACT(D5,E5),"ok","à revoir") | G5: le cas le plus dangereux du module : un total faux, zéro franc, et aucune erreur affichée. Le même =SOMME() sur le CSV importé avec conversion rend 2 444 FCFA — les 3 lignes saisies sans séparateur de milliers (lignes 88, 179, 236), et rien de plus.
A6: 5 | B6: SOMME | C6: SUM(ventes!M2:M481) | D6: 36073185 | E6: =SUM(ventes!M2:M481) | F6: =IF(EXACT(D6,E6),"ok","à revoir") | G6: le total de référence du module, sur la feuille nettoyée
A7: 6 | B7: MOYENNE | C7: AVERAGE(ventes!M2:M481) | D7: 75152 | E7: =AVERAGE(ventes!M2:M481) | F7: =IF(EXACT(D7,E7),"ok","à revoir") | G7: au niveau de la ligne, pas du ticket
A8: 7 | B8: MEDIANE | C8: MEDIAN(ventes!M2:M481) | D8: 37966 | E8: =MEDIAN(ventes!M2:M481) | F8: =IF(EXACT(D8,E8),"ok","à revoir") | G8: le centre robuste du module M02
A9: 8 | B9: ECARTYPE.STANDARD | C9: STDEV.S(ventes!M2:M481) | D9: 143915 | E9: =STDEV.S(ventes!M2:M481) | F9: =IF(EXACT(D9,E9),"ok","à revoir") | G9: dispersion sur échantillon
A10: 9 | B10: MAX | C10: MAX(ventes!M2:M481) | D10: 1229678 | E10: =MAX(ventes!M2:M481) | F10: =IF(EXACT(D10,E10),"ok","à revoir") | G10: et sa voisine MIN, qui est négative
A11: 10 | B11: MIN | C11: MIN(ventes!M2:M481) | D11: -150804 | E11: =MIN(ventes!M2:M481) | F11: =IF(EXACT(D11,E11),"ok","à revoir") | G11: un retour de marchandise, pas une saisie farfelue
A12: 11 | B12: QUARTILE.INC · premier | C12: QUARTILE.INC(ventes!M2:M481,1) | D12: 12950 | E12: =QUARTILE.INC(ventes!M2:M481,1) | F12: =IF(EXACT(D12,E12),"ok","à revoir") | G12: méthode inclusive, celle d'Excel 2010 et suivants
A13: 12 | B13: QUARTILE.INC · troisième | C13: QUARTILE.INC(ventes!M2:M481,3) | D13: 74234 | E13: =QUARTILE.INC(ventes!M2:M481,3) | F13: =IF(EXACT(D13,E13),"ok","à revoir") | G13: le IQR se lit dans la foulée
A14: 13 | B14: NB.SI sur la quantité reçue | C14: COUNTIF(ventes_brutes!I2:I490,">500") | D14: 7 | E14: =COUNTIF(ventes_brutes!I2:I490,">500") | F14: =IF(EXACT(D14,E14),"ok","à revoir") | G14: les sept quantités hors échelle du fichier reçu
A15: 14 | B15: SOMME.SI.ENS catégorie | C15: SUMIFS(ventes!M2:M481,ventes!H2:H481,"Plomberie") | D15: 8754982 | E15: =SUMIFS(ventes!M2:M481,ventes!H2:H481,"Plomberie") | F15: =IF(EXACT(D15,E15),"ok","à revoir") | G15: le CA d'un rayon, une condition
A16: 15 | B16: MOYENNE.SI.ENS | C16: AVERAGEIFS(ventes!M2:M481,ventes!H2:H481,"Electricité") | D16: 119088 | E16: =AVERAGEIFS(ventes!M2:M481,ventes!H2:H481,"Electricité") | F16: =IF(EXACT(D16,E16),"ok","à revoir") | G16: moyenne conditionnelle
A17: 16 | B17: NB.SI.ENS deux conditions | C17: COUNTIFS(ventes!H2:H481,"Peinture",ventes!K2:K481,">0") | D17: 8 | E17: =COUNTIFS(ventes!H2:H481,"Peinture",ventes!K2:K481,">0") | F17: =IF(EXACT(D17,E17),"ok","à revoir") | G17: les lignes remisées du rayon Peinture
A18: 17 | B18: RECHERCHEV, le piège classique | C18: VLOOKUP(1229678,ventes!G2:J481,4,FALSE) | D18: #N/A | E18: =VLOOKUP(1229678,ventes!G2:J481,4,FALSE) | F18: =IF(EXACT(D18,E18),"ok","à revoir") | G18: la valeur cherchée n'est pas dans la PREMIÈRE colonne de la plage : c'est l'exercice 6.2
A19: 18 | B19: RECHERCHEX, le même voyage | C19: XLOOKUP(ventes!M356,ventes!M2:M481,ventes!G2:G481,"non trouvé") | D19: Lame de lambris 4 m — réf 2 | E19: =XLOOKUP(ventes!M356,ventes!M2:M481,ventes!G2:G481,"non trouvé") | F19: =IF(EXACT(D19,E19),"ok","à revoir") | G19: aucun numéro de colonne à compter, et un mot de secours en cas d'absence
A20: 19 | B20: INDEX / EQUIV, la voie compatible | C20: INDEX(ventes!G2:G481,MATCH(MAX(ventes!M2:M481),ventes!M2:M481,0)) | D20: Lame de lambris 4 m — réf 2 | E20: =INDEX(ventes!G2:G481,MATCH(MAX(ventes!M2:M481),ventes!M2:M481,0)) | F20: =IF(EXACT(D20,E20),"ok","à revoir") | G20: ce que vous écrivez en 2019 et sous LibreOffice
A21: 20 | B21: EQUIV · la position | C21: MATCH(MAX(ventes!M2:M481),ventes!M2:M481,0) | D21: 355 | E21: =MATCH(MAX(ventes!M2:M481),ventes!M2:M481,0) | F21: =IF(EXACT(D21,E21),"ok","à revoir") | G21: position dans la plage ; ajoutez 1 pour obtenir la ligne du classeur, et vérifiez : M356
A22: 21 | B22: Tester si la colonne est entièrement numérique | C22: IF(COUNT(ventes_brutes!M2:M490)=COUNTA(ventes_brutes!M2:M490),"tout est nombre","du texte s’est glissé") | D22: du texte s’est glissé | E22: =IF(COUNT(ventes_brutes!M2:M490)=COUNTA(ventes_brutes!M2:M490),"tout est nombre","du texte s’est glissé") | F22: =IF(EXACT(D22,E22),"ok","à revoir") | G22: NB = NBVAL est le test de conformité d'une colonne numérique ; à écrire une fois par fichier, pas une fois par question
A23: 22 | B23: Réparer une cellule | C23: VALUE(SUBSTITUTE(ventes_brutes!M2," ","")) | D23: 56658 | E23: =VALUE(SUBSTITUTE(ventes_brutes!M2," ","")) | F23: =IF(EXACT(D23,E23),"ok","à revoir") | G23: la première ligne du fichier reçu, redevenue un nombre
A24: 23 | B24: Joindre les valeurs distinctes | C24: TEXTJOIN(", ",TRUE,UNIQUE(ventes!H2:H481)) | D24: Matériaux, Consommables, Quincaillerie, Plomberie, Electricité, Peinture, Bois & panneaux | E24: =TEXTJOIN(", ",TRUE,UNIQUE(ventes!H2:H481)) | F24: =IF(EXACT(D24,E24),"ok","à revoir") | G24: les sept rayons en une cellule, dans l'ordre du fichier
A25: 24 | B25: JOURS OUVRES | C25: NETWORKDAYS(DATE(2025,1,1),DATE(2025,12,2)) | D25: 240 | E25: =NETWORKDAYS(DATE(2025,1,1),DATE(2025,12,2)) | F25: =IF(EXACT(D25,E25),"ok","à revoir") | G25: le dénominateur d'une moyenne journalière honnête
A26: 25 | B26: Amplitude réelle de l'extrait | C26: MAX(ventes!B2:B481)-DATE(2025,1,1) | D26: 335 | E26: =MAX(ventes!B2:B481)-DATE(2025,1,1) | F26: =IF(EXACT(D26,E26),"ok","à revoir") | G26: une soustraction de dates rend un nombre de jours ; c'est plus lisible que DATEDIF et cela marche partout
A27: 26 | B27: Attraper l'erreur | C27: IFERROR(1/0,"rien à afficher") | D27: rien à afficher | E27: =IFERROR(1/0,"rien à afficher") | F27: =IF(EXACT(D27,E27),"ok","à revoir") | G27: à n'utiliser que si vous savez quelle erreur vous cachez
A28: 27 | B28: Contrôle de cohérence du montant | C28: ROUND(SUM(ventes!N2:N481)-SUM(ventes!L2:L481),0) | D28: 4 | E28: =ROUND(SUM(ventes!N2:N481)-SUM(ventes!L2:L481),0) | F28: =IF(EXACT(D28,E28),"ok","à revoir") | G28: la colonne utilitaire N recalcule quantité × prix × (1 − remise) ; l'écart avec le montant enregistré doit se compter en francs, pas en milliers
A29: 28 | B29: Réalisation vs objectif, extrait | C29: SUM(ventes!M2:M481)/SUMIFS(objectifs!E2:E219,objectifs!A2:A219,5,objectifs!B2:B219,2025) | D29: 0.182 | E29: =SUM(ventes!M2:M481)/SUMIFS(objectifs!E2:E219,objectifs!A2:A219,5,objectifs!B2:B219,2025) | F29: =IF(EXACT(D29,E29),"ok","à revoir") | G29: 18,2 % : ce ratio compare un extrait de 4 jours par mois à une cible annuelle. Il ne dit rien de la performance

Sheet TCD
A1: categorie | B1: lignes | C1: CA (FCFA) | D1: moyenne par ligne | E1: part du CA | F1: lignes remisées
A2: Matériaux | B2: =COUNTIFS(ventes!H2:H481,$A2) | C2: =SUMIFS(ventes!M2:M481,ventes!H2:H481,$A2) | D2: =IFERROR(C2/B2,"") | E2: =IFERROR(C2/$C$9,"") | F2: =COUNTIFS(ventes!H2:H481,$A2,ventes!K2:K481,">0")
A3: Consommables | B3: =COUNTIFS(ventes!H2:H481,$A3) | C3: =SUMIFS(ventes!M2:M481,ventes!H2:H481,$A3) | D3: =IFERROR(C3/B3,"") | E3: =IFERROR(C3/$C$9,"") | F3: =COUNTIFS(ventes!H2:H481,$A3,ventes!K2:K481,">0")
A4: Quincaillerie | B4: =COUNTIFS(ventes!H2:H481,$A4) | C4: =SUMIFS(ventes!M2:M481,ventes!H2:H481,$A4) | D4: =IFERROR(C4/B4,"") | E4: =IFERROR(C4/$C$9,"") | F4: =COUNTIFS(ventes!H2:H481,$A4,ventes!K2:K481,">0")
A5: Plomberie | B5: =COUNTIFS(ventes!H2:H481,$A5) | C5: =SUMIFS(ventes!M2:M481,ventes!H2:H481,$A5) | D5: =IFERROR(C5/B5,"") | E5: =IFERROR(C5/$C$9,"") | F5: =COUNTIFS(ventes!H2:H481,$A5,ventes!K2:K481,">0")
A6: Electricité | B6: =COUNTIFS(ventes!H2:H481,$A6) | C6: =SUMIFS(ventes!M2:M481,ventes!H2:H481,$A6) | D6: =IFERROR(C6/B6,"") | E6: =IFERROR(C6/$C$9,"") | F6: =COUNTIFS(ventes!H2:H481,$A6,ventes!K2:K481,">0")
A7: Peinture | B7: =COUNTIFS(ventes!H2:H481,$A7) | C7: =SUMIFS(ventes!M2:M481,ventes!H2:H481,$A7) | D7: =IFERROR(C7/B7,"") | E7: =IFERROR(C7/$C$9,"") | F7: =COUNTIFS(ventes!H2:H481,$A7,ventes!K2:K481,">0")
A8: Bois & panneaux | B8: =COUNTIFS(ventes!H2:H481,$A8) | C8: =SUMIFS(ventes!M2:M481,ventes!H2:H481,$A8) | D8: =IFERROR(C8/B8,"") | E8: =IFERROR(C8/$C$9,"") | F8: =COUNTIFS(ventes!H2:H481,$A8,ventes!K2:K481,">0")
A9: Total | B9: =SUM(B2:B8) | C9: =SUM(C2:C8) | D9: =C9/B9 | E9: =SUM(E2:E8) | F9: =SUM(F2:F8)
A11: Le TOTAL de la ligne CA doit être exactement le total de la feuille : s'il diffère d'un centime, un filtre est resté actif quelque part.

Sheet Mensuel
A1: mois | B1: CA de l'extrait (FCFA) | C1: nb de lignes | D1: objectif magasin 5 | E1: CA / objectif | F1: jours ouvrés du mois
A2: 1 | B2: =SUMIFS(ventes!M2:M481,ventes!B2:B481,">="&DATE(2025,$A2,1),ventes!B2:B481,"<"&DATE(2025,$A2+1,1)) | C2: =COUNTIFS(ventes!B2:B481,">="&DATE(2025,$A2,1),ventes!B2:B481,"<"&DATE(2025,$A2+1,1)) | D2: =SUMIFS(objectifs!E2:E219,objectifs!A2:A219,5,objectifs!B2:B219,2025,objectifs!C2:C219,$A2) | E2: =IFERROR(B2/D2,"objectif absent") | F2: =NETWORKDAYS(DATE(2025,$A2,1),EOMONTH(DATE(2025,$A2,1),0))
A3: 2 | B3: =SUMIFS(ventes!M2:M481,ventes!B2:B481,">="&DATE(2025,$A3,1),ventes!B2:B481,"<"&DATE(2025,$A3+1,1)) | C3: =COUNTIFS(ventes!B2:B481,">="&DATE(2025,$A3,1),ventes!B2:B481,"<"&DATE(2025,$A3+1,1)) | D3: =SUMIFS(objectifs!E2:E219,objectifs!A2:A219,5,objectifs!B2:B219,2025,objectifs!C2:C219,$A3) | E3: =IFERROR(B3/D3,"objectif absent") | F3: =NETWORKDAYS(DATE(2025,$A3,1),EOMONTH(DATE(2025,$A3,1),0))
A4: 3 | B4: =SUMIFS(ventes!M2:M481,ventes!B2:B481,">="&DATE(2025,$A4,1),ventes!B2:B481,"<"&DATE(2025,$A4+1,1)) | C4: =COUNTIFS(ventes!B2:B481,">="&DATE(2025,$A4,1),ventes!B2:B481,"<"&DATE(2025,$A4+1,1)) | D4: =SUMIFS(objectifs!E2:E219,objectifs!A2:A219,5,objectifs!B2:B219,2025,objectifs!C2:C219,$A4) | E4: =IFERROR(B4/D4,"objectif absent") | F4: =NETWORKDAYS(DATE(2025,$A4,1),EOMONTH(DATE(2025,$A4,1),0))
A5: 4 | B5: =SUMIFS(ventes!M2:M481,ventes!B2:B481,">="&DATE(2025,$A5,1),ventes!B2:B481,"<"&DATE(2025,$A5+1,1)) | C5: =COUNTIFS(ventes!B2:B481,">="&DATE(2025,$A5,1),ventes!B2:B481,"<"&DATE(2025,$A5+1,1)) | D5: =SUMIFS(objectifs!E2:E219,objectifs!A2:A219,5,objectifs!B2:B219,2025,objectifs!C2:C219,$A5) | E5: =IFERROR(B5/D5,"objectif absent") | F5: =NETWORKDAYS(DATE(2025,$A5,1),EOMONTH(DATE(2025,$A5,1),0))
A6: 5 | B6: =SUMIFS(ventes!M2:M481,ventes!B2:B481,">="&DATE(2025,$A6,1),ventes!B2:B481,"<"&DATE(2025,$A6+1,1)) | C6: =COUNTIFS(ventes!B2:B481,">="&DATE(2025,$A6,1),ventes!B2:B481,"<"&DATE(2025,$A6+1,1)) | D6: =SUMIFS(objectifs!E2:E219,objectifs!A2:A219,5,objectifs!B2:B219,2025,objectifs!C2:C219,$A6) | E6: =IFERROR(B6/D6,"objectif absent") | F6: =NETWORKDAYS(DATE(2025,$A6,1),EOMONTH(DATE(2025,$A6,1),0))
A7: 6 | B7: =SUMIFS(ventes!M2:M481,ventes!B2:B481,">="&DATE(2025,$A7,1),ventes!B2:B481,"<"&DATE(2025,$A7+1,1)) | C7: =COUNTIFS(ventes!B2:B481,">="&DATE(2025,$A7,1),ventes!B2:B481,"<"&DATE(2025,$A7+1,1)) | D7: =SUMIFS(objectifs!E2:E219,objectifs!A2:A219,5,objectifs!B2:B219,2025,objectifs!C2:C219,$A7) | E7: =IFERROR(B7/D7,"objectif absent") | F7: =NETWORKDAYS(DATE(2025,$A7,1),EOMONTH(DATE(2025,$A7,1),0))
A8: 7 | B8: =SUMIFS(ventes!M2:M481,ventes!B2:B481,">="&DATE(2025,$A8,1),ventes!B2:B481,"<"&DATE(2025,$A8+1,1)) | C8: =COUNTIFS(ventes!B2:B481,">="&DATE(2025,$A8,1),ventes!B2:B481,"<"&DATE(2025,$A8+1,1)) | D8: =SUMIFS(objectifs!E2:E219,objectifs!A2:A219,5,objectifs!B2:B219,2025,objectifs!C2:C219,$A8) | E8: =IFERROR(B8/D8,"objectif absent") | F8: =NETWORKDAYS(DATE(2025,$A8,1),EOMONTH(DATE(2025,$A8,1),0))
A9: 8 | B9: =SUMIFS(ventes!M2:M481,ventes!B2:B481,">="&DATE(2025,$A9,1),ventes!B2:B481,"<"&DATE(2025,$A9+1,1)) | C9: =COUNTIFS(ventes!B2:B481,">="&DATE(2025,$A9,1),ventes!B2:B481,"<"&DATE(2025,$A9+1,1)) | D9: =SUMIFS(objectifs!E2:E219,objectifs!A2:A219,5,objectifs!B2:B219,2025,objectifs!C2:C219,$A9) | E9: =IFERROR(B9/D9,"objectif absent") | F9: =NETWORKDAYS(DATE(2025,$A9,1),EOMONTH(DATE(2025,$A9,1),0))
A10: 9 | B10: =SUMIFS(ventes!M2:M481,ventes!B2:B481,">="&DATE(2025,$A10,1),ventes!B2:B481,"<"&DATE(2025,$A10+1,1)) | C10: =COUNTIFS(ventes!B2:B481,">="&DATE(2025,$A10,1),ventes!B2:B481,"<"&DATE(2025,$A10+1,1)) | D10: =SUMIFS(objectifs!E2:E219,objectifs!A2:A219,5,objectifs!B2:B219,2025,objectifs!C2:C219,$A10) | E10: =IFERROR(B10/D10,"objectif absent") | F10: =NETWORKDAYS(DATE(2025,$A10,1),EOMONTH(DATE(2025,$A10,1),0))
A11: 10 | B11: =SUMIFS(ventes!M2:M481,ventes!B2:B481,">="&DATE(2025,$A11,1),ventes!B2:B481,"<"&DATE(2025,$A11+1,1)) | C11: =COUNTIFS(ventes!B2:B481,">="&DATE(2025,$A11,1),ventes!B2:B481,"<"&DATE(2025,$A11+1,1)) | D11: =SUMIFS(objectifs!E2:E219,objectifs!A2:A219,5,objectifs!B2:B219,2025,objectifs!C2:C219,$A11) | E11: =IFERROR(B11/D11,"objectif absent") | F11: =NETWORKDAYS(DATE(2025,$A11,1),EOMONTH(DATE(2025,$A11,1),0))
A12: 11 | B12: =SUMIFS(ventes!M2:M481,ventes!B2:B481,">="&DATE(2025,$A12,1),ventes!B2:B481,"<"&DATE(2025,$A12+1,1)) | C12: =COUNTIFS(ventes!B2:B481,">="&DATE(2025,$A12,1),ventes!B2:B481,"<"&DATE(2025,$A12+1,1)) | D12: =SUMIFS(objectifs!E2:E219,objectifs!A2:A219,5,objectifs!B2:B219,2025,objectifs!C2:C219,$A12) | E12: =IFERROR(B12/D12,"objectif absent") | F12: =NETWORKDAYS(DATE(2025,$A12,1),EOMONTH(DATE(2025,$A12,1),0))
A13: 12 | B13: =SUMIFS(ventes!M2:M481,ventes!B2:B481,">="&DATE(2025,$A13,1),ventes!B2:B481,"<"&DATE(2025,$A13+1,1)) | C13: =COUNTIFS(ventes!B2:B481,">="&DATE(2025,$A13,1),ventes!B2:B481,"<"&DATE(2025,$A13+1,1)) | D13: =SUMIFS(objectifs!E2:E219,objectifs!A2:A219,5,objectifs!B2:B219,2025,objectifs!C2:C219,$A13) | E13: =IFERROR(B13/D13,"objectif absent") | F13: =NETWORKDAYS(DATE(2025,$A13,1),EOMONTH(DATE(2025,$A13,1),0))
A15: Total | B15: =SUM(B2:B13) | C15: =SUM(C2:C13) | D15: =SUM(D2:D13) | E15: =IFERROR(B15/D15,"")
A17: Lecture honnête du ratio CA / objectif : ici l'extrait ne couvre que les jours 1 à 4 de chaque mois (voir M02.C07), donc ce ratio ne mesure PAS la performance annuelle du magasin. Il mesure un extrait. La population entière donne un rapport de 1.62 à 3.27 selon le magasin-mois (le projet M03.P le discutera avec le fichier complet) : avant de parler de surperformance, on vérifie l'échelle du fichier d'objectifs.
